<sdf version='1.7'>
    <model name='tarot_drone_custom_v3'>
      <link name='L1'>
  
  
        <sensor name="gps" type="gps">
  
          <pose>0 0 0 0 0 0</pose>
          <update_rate>5.0</update_rate>
          <always_on>true</always_on>
          <visualize>false</visualize>
          <plugin name="gps_plugin" filename="libgazebo_gps_plugin.so">
            <robotNamespace></robotNamespace>
            <topic>/gps</topic>
            <gpsNoise>true</gpsNoise>
            <gpsXYRandomWalk>2.0</gpsXYRandomWalk>
            <gpsZRandomWalk>4.0</gpsZRandomWalk>
            <gpsXYNoiseDensity>2.0e-4</gpsXYNoiseDensity>
            <gpsZNoiseDensity>4.0e-4</gpsZNoiseDensity>
            <gpsVXYNoiseDensity>0.2</gpsVXYNoiseDensity>
            <gpsVZNoiseDensity>0.4</gpsVZNoiseDensity>
          </plugin>
        </sensor>
  
  
        <inertial>
          <pose>-0.008585 -0.128542 0.236472 0 -0 0</pose>
          <mass>2.2</mass>
          <!-- was 0.98937 -->
          <inertia>
            <!--
              <ixx>0.0257323</ixx>
              <ixy>-3.3722e-05</ixy>
              <ixz>-0.000448122</ixz>
              <iyy>0.0245817</iyy>
              <iyz>-3.29026e-05</iyz>
              <izz>0.049121</izz>
              -->
  
            <ixx>0.011</ixx>
            <ixy>0</ixy>
            <ixz>0</ixz>
            <iyy>0.015</iyy>
            <iyz>0</iyz>
            <izz>0.021</izz>
          </inertia>
        </inertial>
  
  
        <!-- collision is below-->
        <collision name='L1_collision'>
          <pose>0 0 0.254 0 0 0</pose>
          <geometry>
            <box>
              <size>1 1 0.54</size>
            </box>
          </geometry>
          <surface>
            <contact>
              <ode>
                <min_depth>0.001</min_depth>
                <max_vel>0</max_vel>
              </ode>
            </contact>
            <friction>
              <ode>
                <mu>1</mu>
                <mu2>1</mu2>
              </ode>
            </friction>
          </surface>
        </collision>
  
        <!-- visual is below-->
        <visual name='L1_visual'>
          <pose>0 0 0 0 -0 0</pose>
          <geometry>
            <mesh>
              <scale>1 1 1</scale>
              <uri>model://tarot_drone_custom/meshes/L1.STL</uri>
            </mesh>
          </geometry>
        </visual>
        <visual name='L1_fixed_joint_lump__arm1_visual_1'>
          <pose>-0.07976 -0.070711 0.07883 1.5796 -0.093345 -0.52435</pose>
          <geometry>
            <mesh>
              <scale>1 1 1</scale>
              <uri>model://tarot_drone_custom/meshes/arm1.STL</uri>
            </mesh>
          </geometry>
        </visual>
        <visual name='L1_fixed_joint_lump__arm2_visual_2'>
          <pose>-0.093645 -0.16386 0.078587 1.562 -0.093345 0.52435</pose>
          <geometry>
            <mesh>
              <scale>1 1 1</scale>
              <uri>model://tarot_drone_custom/meshes/arm2.STL</uri>
            </mesh>
          </geometry>
        </visual>
        <visual name='L1_fixed_joint_lump__arm3_visual_3'>
          <pose>-0.033857 -0.22248 0.079751 1.5533 -0.078222 1.5722</pose>
          <geometry>
            <mesh>
              <scale>1 1 1</scale>
              <uri>model://tarot_drone_custom/meshes/arm3.STL</uri>
            </mesh>
          </geometry>
        </visual>
        <visual name='L1_fixed_joint_lump__arm4_visual_4'>
          <pose>0.067676 -0.18801 0.081403 1.5621 -0.063116 2.6186</pose>
          <geometry>
            <mesh>
              <scale>1 1 1</scale>
              <uri>model://tarot_drone_custom/meshes/arm4.STL</uri>
            </mesh>
          </geometry>
        </visual>
        <visual name='L1_fixed_joint_lump__arm5_visual_5'>
          <pose>0.081562 -0.094858 0.081645 1.5795 -0.063116 -2.6186</pose>
          <geometry>
            <mesh>
              <scale>1 1 1</scale>
              <uri>model://tarot_drone_custom/meshes/arm5.STL</uri>
            </mesh>
          </geometry>
        </visual>
        <visual name='L1_fixed_joint_lump__arm6_visual_6'>
          <pose>0.021769 -0.036178 0.080722 1.5883 -0.078222 -1.5722</pose>
          <geometry>
            <mesh>
              <scale>1 1 1</scale>
              <uri>model://tarot_drone_custom/meshes/arm6.STL</uri>
            </mesh>
          </geometry>
        </visual>
        <visual name='L1_fixed_joint_lump__t1_visual_7'>
          <pose>-0.12808 -0.27468 0.019425 0 -1.5432 0</pose>
          <geometry>
            <mesh>
              <scale>1 1 1</scale>
              <uri>model://tarot_drone_custom/meshes/t1.STL</uri>
            </mesh>
          </geometry>
        </visual>
      </link>
  
  
      <!-- rotor 1 -->
      <joint name='R1' type='revolute'>
        <pose relative_to='L1'>0.329812 -0.128776 0.282859 -1.55961 -0.013381 -0.694065</pose>
        <parent>L1</parent>
        <child>rotor1</child>
        <axis>
          <xyz>0 1 0</xyz>
          <limit>
            <lower>-1e+16</lower>
            <upper>1e+16</upper>
            <effort>10</effort>
            <velocity>-1</velocity>
          </limit>
          <dynamics>
            <damping>0.005</damping>
          </dynamics>
        </axis>
        <physics>
          <ode>
            <implicit_spring_damper>1</implicit_spring_damper>
          </ode>
        </physics>
      </joint>
      <link name='rotor1'>
        <pose relative_to='R1'>0 0 0 0 -0 0</pose>
        <inertial>
          <pose>0 -0.002498 0 0 -0 0</pose>
          <mass>0.005</mass>
          <inertia>
            <ixx>9.75e-07</ixx>
            <ixy>0</ixy>
            <ixz>0</ixz>
            <iyy>0.000273104</iyy>
            <iyz>0</iyz>
            <izz>0.000274004</izz>
          </inertia>
        </inertial>
        <collision name='rotor1_collision'>
          <pose>0 0 0 0 -0 0</pose>
          <geometry>
            <mesh>
              <scale>1 1 1</scale>
              <uri>model://tarot_drone_custom/meshes/rotor1.STL</uri>
            </mesh>
          </geometry>
        </collision>
        <visual name='rotor1_visual'>
          <pose relative_to='R1'> 0 0 0 0 0 0</pose>
          <geometry>
            <mesh>
                <scale>1 1 1</scale>
                <uri>model://tarot_drone_custom/meshes/rotor1.STL</uri>
            </mesh>
          </geometry>
          <material>
            <script>
              <name>Gazebo/Blue</name>
              <uri>file://media/materials/scripts/gazebo.material</uri>
            </script>
          </material>
        </visual>
      </link>
  
  
      <joint name='R2' type='revolute'>
        <pose relative_to='L1'>-0.348771 -0.129856 0.271019 -1.56159 -0.01483 -0.5552</pose>
        <parent>L1</parent>
        <child>rotor2</child>
        <axis>
          <xyz>0 1 0</xyz>
          <limit>
            <lower>-1e+16</lower>
            <upper>1e+16</upper>
            <effort>10</effort>
            <velocity>-1</velocity>
          </limit>
          <dynamics>
            <damping>0.005</damping>
          </dynamics>
        </axis>
        <physics>
          <ode>
            <implicit_spring_damper>1</implicit_spring_damper>
          </ode>
        </physics>
      </joint>
      <link name='rotor2'>
        <pose relative_to='R2'>0 0 0 0 -0 0</pose>
        <inertial>
          <pose>0 -0.002498 0 0 -0 0</pose>
          <mass>0.005</mass>
          <inertia>
            <ixx>9.75e-07</ixx>
            <ixy>0</ixy>
            <ixz>0</ixz>
            <iyy>0.000273104</iyy>
            <iyz>0</iyz>
            <izz>0.000274004</izz>
          </inertia>
        </inertial>
        <collision name='rotor2_collision'>
          <pose>0 0 0 0 -0 0</pose>
          <geometry>
            <mesh>
              <scale>1 1 1</scale>
              <uri>model://tarot_drone_custom/meshes/rotor2.STL</uri>
            </mesh>
          </geometry>
        </collision>
        <visual name='rotor2_visual'>
          <pose relative_to='R2'> 0 0 0 0 0 0</pose>
          <geometry>
            <mesh>
                <scale>1 1 1</scale>
                <uri>model://tarot_drone_custom/meshes/rotor2.STL</uri>
            </mesh>
          </geometry>
          <material>
            <script>
              <name>Gazebo/Gray</name>
              <uri>file://media/materials/scripts/gazebo.material</uri>
            </script>
          </material>
        </visual>
      </link>
  
  
      <joint name='R3' type='revolute'>
        <pose relative_to='L1'>-0.186549 0.176257 0.273744 -1.58819 -0.000438 1.54641</pose>
        <parent>L1</parent>
        <child>rotor3</child>
        <axis>
          <xyz>0 1 0</xyz>
          <limit>
            <lower>-1e+16</lower>
            <upper>1e+16</upper>
            <effort>10</effort>
            <velocity>-1</velocity>
          </limit>
          <dynamics>
            <damping>0.005</damping>
          </dynamics>
        </axis>
        <physics>
          <ode>
            <implicit_spring_damper>1</implicit_spring_damper>
          </ode>
        </physics>
      </joint>
      <link name='rotor3'>
        <pose relative_to='R3'>0 0 0 0 -0 0</pose>
        <inertial>
          <pose>-0 -0.002498 -0 0 -0 0</pose>
          <mass>0.005</mass>
          <inertia>
            <ixx>9.75e-07</ixx>
            <ixy>0</ixy>
            <ixz>0</ixz>
            <iyy>0.000273104</iyy>
            <iyz>0</iyz>
            <izz>0.000274004</izz>
          </inertia>
        </inertial>
        <collision name='rotor3_collision'>
          <pose>0 0 0 0 -0 0</pose>
          <geometry>
            <mesh>
              <scale>1 1 1</scale>
              <uri>model://tarot_drone_custom/meshes/rotor3.STL</uri>
            </mesh>
          </geometry>
        </collision>
        <visual name='rotor3_visual'>
          <pose relative_to='R3'> 0 0 0 0 0 0</pose>
          <geometry>
            <mesh>
                <scale>1 1 1</scale>
                <uri>model://tarot_drone_custom/meshes/rotor3.STL</uri>
            </mesh>
          </geometry>
          <material>
            <script>
              <name>Gazebo/Blue</name>
              <uri>file://media/materials/scripts/gazebo.material</uri>
            </script>
          </material>
        </visual>
      </link>
  
  
      <joint name='R4' type='revolute'>
        <pose relative_to='L1'>0.167596 -0.43498 0.279923 -1.56472 0.016418 -2.78779</pose>
        <parent>L1</parent>
        <child>rotor4</child>
        <axis>
          <xyz>0 1 0</xyz>
          <limit>
            <lower>-1e+16</lower>
            <upper>1e+16</upper>
            <effort>10</effort>
            <velocity>-1</velocity>
          </limit>
          <dynamics>
            <damping>0.005</damping>
          </dynamics>
        </axis>
        <physics>
          <ode>
            <implicit_spring_damper>1</implicit_spring_damper>
          </ode>
        </physics>
      </joint>
      <link name='rotor4'>
        <pose relative_to='R4'>0 0 0 0 -0 0</pose>
        <inertial>
          <pose>-0 -0.002498 0 0 -0 0</pose>
          <mass>0.005</mass>
          <inertia>
            <ixx>9.75e-07</ixx>
            <ixy>0</ixy>
            <ixz>0</ixz>
            <iyy>0.000273104</iyy>
            <iyz>0</iyz>
            <izz>0.000274004</izz>
          </inertia>
        </inertial>
        <collision name='rotor4_collision'>
          <pose>0 0 0 0 -0 0</pose>
          <geometry>
            <mesh>
              <scale>1 1 1</scale>
              <uri>model://tarot_drone_custom/meshes/rotor4.STL</uri>
            </mesh>
          </geometry>
        </collision>
        <visual name='rotor4_visual'>
          <pose relative_to='R4'> 0 0 0 0 0 0</pose>
          <geometry>
            <mesh>
                <scale>1 1 1</scale>
                <uri>model://tarot_drone_custom/meshes/rotor4.STL</uri>
            </mesh>
          </geometry>
          <material>
            <script>
              <name>Gazebo/Gray</name>
              <uri>file://media/materials/scripts/gazebo.material</uri>
            </script>
          </material>
        </visual>
      </link>
  
      <joint name='R5' type='revolute'>
        <pose relative_to='L1'>0.166676 0.176813 0.279878 -1.58118 0.013992 2.5003</pose>
        <parent>L1</parent>
        <child>rotor5</child>
        <axis>
          <xyz>0 1 0</xyz>
          <limit>
            <lower>-1e+16</lower>
            <upper>1e+16</upper>
            <effort>10</effort>
            <velocity>-1</velocity>
          </limit>
          <dynamics>
            <damping>0.005</damping>
          </dynamics>
        </axis>
        <physics>
          <ode>
            <implicit_spring_damper>1</implicit_spring_damper>
          </ode>
        </physics>
      </joint>
      <link name='rotor5'>
        <pose relative_to='R5'>0 0 0 0 -0 0</pose>
        <inertial>
          <pose>-0 -0.002498 -0 0 -0 0</pose>
          <mass>0.005</mass>
          <inertia>
            <ixx>9.75e-07</ixx>
            <ixy>0</ixy>
            <ixz>0</ixz>
            <iyy>0.000273104</iyy>
            <iyz>0</iyz>
            <izz>0.000274004</izz>
          </inertia>
        </inertial>
        <collision name='rotor5_collision'>
          <pose>0 0 0 0 -0 0</pose>
          <geometry>
            <mesh>
              <scale>1 1 1</scale>
              <uri>model://tarot_drone_custom/meshes/rotor5.STL</uri>
            </mesh>
          </geometry>
        </collision>
        <visual name='rotor5_visual'>
          <pose relative_to='R5'> 0 0 0 0 0 0</pose>
          <geometry>
            <mesh>
                <scale>1 1 1</scale>
                <uri>model://tarot_drone_custom/meshes/rotor5.STL</uri>
            </mesh>
          </geometry>
          <material>
            <script>
              <name>Gazebo/Gray</name>
              <uri>file://media/materials/scripts/gazebo.material</uri>
            </script>
          </material>
        </visual>
      </link>
  
  
      <joint name='R6' type='revolute'>
        <pose relative_to='L1'>-0.185622 -0.435533 0.273732 -1.58817 0.002179 1.69636</pose>
        <parent>L1</parent>
        <child>rotor6</child>
        <axis>
          <xyz>0 1 0</xyz>
          <limit>
            <lower>-1e+16</lower>
            <upper>1e+16</upper>
            <effort>10</effort>
            <velocity>-1</velocity>
          </limit>
          <dynamics>
            <damping>0.005</damping>
          </dynamics>
        </axis>
        <physics>
          <ode>
            <implicit_spring_damper>1</implicit_spring_damper>
          </ode>
        </physics>
      </joint>
      <link name='rotor6'>
        <pose relative_to='R6'>0 0 0 0 -0 0</pose>
        <inertial>
          <pose>-0 -0.002498 -0 0 -0 0</pose>
          <mass>0.005</mass>
          <inertia>
            <ixx>9.75e-07</ixx>
            <ixy>0</ixy>
            <ixz>0</ixz>
            <iyy>0.000273104</iyy>
            <iyz>0</iyz>
            <izz>0.000274004</izz>
          </inertia>
        </inertial>
        <collision name='rotor6_collision'>
          <pose>0 0 0 0 -0 0</pose>
          <geometry>
            <mesh>
              <scale>1 1 1</scale>
              <uri>model://tarot_drone_custom/meshes/rotor6.STL</uri>
            </mesh>
          </geometry>
        </collision>
        <visual name='rotor6_visual'>
          <pose relative_to='R6'> 0 0 0 0 0 0</pose>
          <geometry>
            <mesh>
                <scale>1 1 1</scale>
                <uri>model://tarot_drone_custom/meshes/rotor6.STL</uri>
            </mesh>
          </geometry>
          <material>
            <script>
              <name>Gazebo/Blue</name>
              <uri>file://media/materials/scripts/gazebo.material</uri>
            </script>
          </material>
        </visual>
      </link>
  
  
      <include>
        <uri>model://gps</uri>
        <pose relative_to='L1'>0 -0.12 0.254 0 0 0</pose>
        <name>gps</name>
      </include>
  
      <joint name='gps_joint' type='fixed'>
        <child>gps::link</child>
        <parent>L1</parent>
      </joint>
  
      <plugin name='rosbag' filename='libgazebo_multirotor_base_plugin.so'>
        <robotNamespace></robotNamespace>
        <linkName>L1</linkName>
        <rotorVelocitySlowdownSim>10</rotorVelocitySlowdownSim>
      </plugin>
  
      <plugin name='front_right_motor_model' filename='libgazebo_motor_model.so'>
        <robotNamespace></robotNamespace>
        <jointName>R6</jointName>
        <linkName>rotor6</linkName>
        <turningDirection>ccw</turningDirection>
        <timeConstantUp>0.0125</timeConstantUp>
        <timeConstantDown>0.025</timeConstantDown>
        <maxRotVelocity>3000</maxRotVelocity>
        <motorConstant>8.54858e-06</motorConstant>
        <momentConstant>0.06</momentConstant>
        <commandSubTopic>/gazebo/command/motor_speed</commandSubTopic>
        <motorNumber>5</motorNumber> <!-- corresponds to actual numbers from documenation -->
        <rotorDragCoefficient>0.000806428</rotorDragCoefficient>
        <rollingMomentCoefficient>1e-06</rollingMomentCoefficient>
        <motorSpeedPubTopic>/motor_speed/5</motorSpeedPubTopic>
        <rotorVelocitySlowdownSim>10</rotorVelocitySlowdownSim>
      </plugin>
      <plugin name='back_right_motor_model' filename='libgazebo_motor_model.so'>
        <robotNamespace></robotNamespace>
        <jointName>R3</jointName>
        <linkName>rotor3</linkName>
        <turningDirection>ccw</turningDirection>
        <timeConstantUp>0.0125</timeConstantUp>
        <timeConstantDown>0.025</timeConstantDown>
        <maxRotVelocity>3000</maxRotVelocity>
        <motorConstant>8.54858e-06</motorConstant>
        <momentConstant>0.06</momentConstant>
        <commandSubTopic>/gazebo/command/motor_speed</commandSubTopic>
        <motorNumber>4</motorNumber>
        <rotorDragCoefficient>0.000806428</rotorDragCoefficient>
        <rollingMomentCoefficient>1e-06</rollingMomentCoefficient>
        <motorSpeedPubTopic>/motor_speed/4</motorSpeedPubTopic>
        <rotorVelocitySlowdownSim>10</rotorVelocitySlowdownSim>
      </plugin>
  
  
      <plugin name='front_left_motor_model' filename='libgazebo_motor_model.so'>
        <robotNamespace></robotNamespace>
        <jointName>R4</jointName>
        <linkName>rotor4</linkName>
        <turningDirection>cw</turningDirection>
        <timeConstantUp>0.0125</timeConstantUp>
        <timeConstantDown>0.025</timeConstantDown>
        <maxRotVelocity>3000</maxRotVelocity>
        <motorConstant>8.54858e-06</motorConstant>
        <momentConstant>0.06</momentConstant>
        <commandSubTopic>/gazebo/command/motor_speed</commandSubTopic>
        <motorNumber>3</motorNumber>
        <rotorDragCoefficient>0.000806428</rotorDragCoefficient>
        <rollingMomentCoefficient>1e-06</rollingMomentCoefficient>
        <motorSpeedPubTopic>/motor_speed/3</motorSpeedPubTopic>
        <rotorVelocitySlowdownSim>10</rotorVelocitySlowdownSim>
      </plugin>
      <plugin name='back_left_motor_model' filename='libgazebo_motor_model.so'>
        <robotNamespace></robotNamespace>
        <jointName>R5</jointName>
        <linkName>rotor5</linkName>
        <turningDirection>cw</turningDirection>
        <timeConstantUp>0.0125</timeConstantUp>
        <timeConstantDown>0.025</timeConstantDown>
        <maxRotVelocity>3000</maxRotVelocity>
        <motorConstant>8.54858e-06</motorConstant>
        <momentConstant>0.06</momentConstant>
        <commandSubTopic>/gazebo/command/motor_speed</commandSubTopic>
        <motorNumber>6</motorNumber>
        <rotorDragCoefficient>0.000806428</rotorDragCoefficient>
        <rollingMomentCoefficient>1e-06</rollingMomentCoefficient>
        <motorSpeedPubTopic>/motor_speed/6</motorSpeedPubTopic>
        <rotorVelocitySlowdownSim>10</rotorVelocitySlowdownSim>
      </plugin>
  
      <!-- may need to change 6 to 0 -->
  
  
      <!-- may need to change to back left -->
      <plugin name='back_left_motor_model' filename='libgazebo_motor_model.so'>
        <robotNamespace></robotNamespace>
        <jointName>R1</jointName>
        <linkName>rotor1</linkName>
        <turningDirection>ccw</turningDirection>
        <timeConstantUp>0.0125</timeConstantUp>
        <timeConstantDown>0.025</timeConstantDown>
        <maxRotVelocity>3000</maxRotVelocity>
        <motorConstant>8.54858e-06</motorConstant>
        <momentConstant>0.06</momentConstant>
        <commandSubTopic>/gazebo/command/motor_speed</commandSubTopic>
        <motorNumber>2</motorNumber>
        <rotorDragCoefficient>0.000806428</rotorDragCoefficient>
        <rollingMomentCoefficient>1e-06</rollingMomentCoefficient>
        <motorSpeedPubTopic>/motor_speed/2</motorSpeedPubTopic>
        <rotorVelocitySlowdownSim>10</rotorVelocitySlowdownSim>
      </plugin>
  
  
      <plugin name='back_right_motor_model' filename='libgazebo_motor_model.so'>
        <robotNamespace></robotNamespace>
        <jointName>R2</jointName>
        <linkName>rotor2</linkName>
        <turningDirection>cw</turningDirection>
        <timeConstantUp>0.0125</timeConstantUp>
        <timeConstantDown>0.025</timeConstantDown>
        <maxRotVelocity>3000</maxRotVelocity>
        <motorConstant>8.54858e-06</motorConstant>
        <momentConstant>0.06</momentConstant>
        <commandSubTopic>/gazebo/command/motor_speed</commandSubTopic>
        <motorNumber>1</motorNumber>
        <rotorDragCoefficient>0.000806428</rotorDragCoefficient>
        <rollingMomentCoefficient>1e-06</rollingMomentCoefficient>
        <motorSpeedPubTopic>/motor_speed/1</motorSpeedPubTopic>
        <rotorVelocitySlowdownSim>10</rotorVelocitySlowdownSim>
      </plugin>
  
  
      <plugin name='groundtruth_plugin' filename='libgazebo_groundtruth_plugin.so'>
        <robotNamespace />
      </plugin>
  
      <plugin name='magnetometer_plugin' filename='libgazebo_magnetometer_plugin.so'>
        <robotNamespace />
        <pubRate>100</pubRate>
        <noiseDensity>0.0004</noiseDensity>
        <randomWalk>6.4e-06</randomWalk>
        <biasCorrelationTime>600</biasCorrelationTime>
        <magTopic>/mag</magTopic>
      </plugin>
      <plugin name='barometer_plugin' filename='libgazebo_barometer_plugin.so'>
        <robotNamespace />
        <pubRate>50</pubRate>
        <baroTopic>/baro</baroTopic>
      </plugin>
  
      <plugin name='mavlink_interface' filename='libgazebo_mavlink_interface.so'>
        <robotNamespace></robotNamespace>
        <imuSubTopic>/imu</imuSubTopic>
        <magSubTopic>/mag</magSubTopic>
        <baroSubTopic>/baro</baroSubTopic>
        <mavlink_addr>INADDR_ANY</mavlink_addr>
        <mavlink_tcp_port>4560</mavlink_tcp_port>
        <mavlink_udp_port>14560</mavlink_udp_port>
        <serialEnabled>0</serialEnabled>
        <serialDevice>/dev/ttyACM0</serialDevice>
        <baudRate>921600</baudRate>
        <qgc_addr>INADDR_ANY</qgc_addr>
        <qgc_udp_port>14550</qgc_udp_port>
        <sdk_addr>INADDR_ANY</sdk_addr>
        <sdk_udp_port>14540</sdk_udp_port>
        <hil_mode>0</hil_mode>
        <hil_state_level>false</hil_state_level>
        <enable_lockstep>true</enable_lockstep>
        <use_tcp>true</use_tcp>
        <motorSpeedCommandPubTopic>/gazebo/command/motor_speed</motorSpeedCommandPubTopic>
        <control_channels>
          <channel name="rotor1">
            <input_index>1</input_index>
            <input_offset>0</input_offset>
            <input_scaling>1500</input_scaling>
            <zero_position_disarmed>0</zero_position_disarmed>
            <zero_position_armed>100</zero_position_armed>
            <joint_control_type>velocity</joint_control_type>
          </channel>
          <channel name="rotor2">
            <input_index>2</input_index>
            <input_offset>0</input_offset>
            <input_scaling>1500</input_scaling>
            <zero_position_disarmed>0</zero_position_disarmed>
            <zero_position_armed>100</zero_position_armed>
            <joint_control_type>velocity</joint_control_type>
          </channel>
  
          <channel name="rotor3">
            <input_index>3</input_index>
            <input_offset>0</input_offset>
            <input_scaling>1500</input_scaling>
            <zero_position_disarmed>0</zero_position_disarmed>
            <zero_position_armed>100</zero_position_armed>
            <joint_control_type>velocity</joint_control_type>
          </channel>
  
  
          <channel name="rotor4">
            <input_index>4</input_index>
            <input_offset>0</input_offset>
            <input_scaling>1500</input_scaling>
            <zero_position_disarmed>0</zero_position_disarmed>
            <zero_position_armed>100</zero_position_armed>
            <joint_control_type>velocity</joint_control_type>
          </channel>
  
  
          <channel name="rotor5">
            <input_index>5</input_index>
            <input_offset>0</input_offset>
            <input_scaling>1500</input_scaling>
            <zero_position_disarmed>0</zero_position_disarmed>
            <zero_position_armed>100</zero_position_armed>
            <joint_control_type>velocity</joint_control_type>
          </channel>
  
  
          <channel name="rotor6">
            <input_index>6</input_index>
            <input_offset>0</input_offset>
            <input_scaling>1500</input_scaling>
            <zero_position_disarmed>0</zero_position_disarmed>
            <zero_position_armed>100</zero_position_armed>
            <joint_control_type>velocity</joint_control_type>
          </channel>
  
  
        </control_channels>
      </plugin>
  
  
      <plugin name='gazebo_imu_plugin' filename='libgazebo_imu_plugin.so'>
        <robotNamespace></robotNamespace>
        <linkName>L1</linkName>
        <imuTopic>/imu</imuTopic>
        <gyroscopeNoiseDensity>0.0003394</gyroscopeNoiseDensity>
        <gyroscopeRandomWalk>3.8785e-05</gyroscopeRandomWalk>
        <gyroscopeBiasCorrelationTime>1000.0</gyroscopeBiasCorrelationTime>
        <gyroscopeTurnOnBiasSigma>0.0087</gyroscopeTurnOnBiasSigma>
        <accelerometerNoiseDensity>0.004</accelerometerNoiseDensity>
        <accelerometerRandomWalk>0.006</accelerometerRandomWalk>
        <accelerometerBiasCorrelationTime>300.0</accelerometerBiasCorrelationTime>
        <accelerometerTurnOnBiasSigma>0.196</accelerometerTurnOnBiasSigma>
      </plugin>
  
  
    </model>
  </sdf>