<sdf version='1.7'>
    <model name='tarot_drone_custom_v3'>
        <link name='L1'>


            <inertial>
                <pose>0 0 0.1 0 -0 0</pose>
                <mass>5</mass>
                <!-- was 0.98937 -->
                <inertia>
                    <!--
              <ixx>0.0257323</ixx>
              <ixy>-3.3722e-05</ixy>
              <ixz>-0.000448122</ixz>
              <iyy>0.0245817</iyy>
              <iyz>-3.29026e-05</iyz>
              <izz>0.049121</izz>
              -->

                    <ixx>1</ixx>
                    <ixy>0</ixy>
                    <ixz>0</ixz>
                    <iyy>1</iyy>
                    <iyz>0</iyz>
                    <izz>1</izz>
                </inertia>
            </inertial>


            <!-- collision is below-->
            <collision name='L1_collision'>
                <pose>0 0 0.1 0 0 0</pose>
                <geometry>
                    <cylinder>
                        <radius>1</radius>
                        <length>0.2</length>
                    </cylinder>
                </geometry>
                <surface>
                    <contact>
                        <ode>
                            <min_depth>0.001</min_depth>
                            <max_vel>0</max_vel>
                        </ode>
                    </contact>
                    <friction>
                        <ode>
                            <mu>1</mu>
                            <mu2>1</mu2>
                        </ode>
                    </friction>
                </surface>
            </collision>

            <!-- visual is below-->
            <visual name='L1_visual'>
                <pose>0 0 0.1 0 0 0</pose>
                <geometry>
                    <cylinder>
                        <radius>1</radius>
                        <length>0.2</length>
                    </cylinder>
                </geometry>
            </visual>


            <sensor name="gps" type="gps">

                <pose>0 0 0.2 0 0 0</pose>
                <update_rate>5.0</update_rate>
                <always_on>true</always_on>
                <visualize>false</visualize>
                <plugin name="gps_plugin" filename="libgazebo_gps_plugin.so">
                    <robotNamespace></robotNamespace>
                    <topic>/gps</topic>
                    <gpsNoise>true</gpsNoise>
                    <gpsXYRandomWalk>2.0</gpsXYRandomWalk>
                    <gpsZRandomWalk>4.0</gpsZRandomWalk>
                    <gpsXYNoiseDensity>2.0e-4</gpsXYNoiseDensity>
                    <gpsZNoiseDensity>4.0e-4</gpsZNoiseDensity>
                    <gpsVXYNoiseDensity>0.2</gpsVXYNoiseDensity>
                    <gpsVZNoiseDensity>0.4</gpsVZNoiseDensity>
                </plugin>
            </sensor>
        </link>


        <!-- rotor 1 -->
        <link name='rotor1'>
            <pose>1 0 0.21 0 0 0</pose>
            <inertial>
                <pose>0 0 0 0 0 0</pose>
                <mass>0.005</mass>
                <inertia>
                    <ixx>9.75e-07</ixx>
                    <ixy>0</ixy>
                    <ixz>0</ixz>
                    <iyy>0.000273104</iyy>
                    <iyz>0</iyz>
                    <izz>0.000274004</izz>
                </inertia>
            </inertial>
            <collision name='rotor_1_collision'>
                <pose>0 0 0 0 0 0</pose>
                <geometry>
                    <cylinder>
                        <length>0.0005</length>
                        <radius>0.128</radius>
                    </cylinder>
                </geometry>
                <surface>
                    <contact>
                        <ode />
                    </contact>
                    <friction>
                        <ode />
                    </friction>
                </surface>
            </collision>
            <visual name='rotor_1_visual'>
                <pose>0 0 0 0 0 0</pose>
                <geometry>
                    <mesh>
                        <scale>1 1 1</scale>
                        <uri>model://tarot_drone_custom/meshes/iris_prop_cw.dae</uri>
                    </mesh>
                </geometry>
                <material>
                    <script>
                        <name>Gazebo/Blue</name>
                        <uri>file://media/materials/scripts/gazebo.material</uri>
                    </script>
                </material>
            </visual>
            <gravity>1</gravity>
            <velocity_decay />
        </link>
        <joint name='R1' type='revolute'>
            <child>rotor1</child>
            <parent>L1</parent>
            <axis>
                <xyz>0 0 1</xyz>
                <limit>
                    <lower>-1e+16</lower>
                    <upper>1e+16</upper>
                    <effort>10</effort>
                    <velocity>-1</velocity>
                </limit>
                <dynamics>
                    <damping>0.005</damping>
                </dynamics>
                <use_parent_model_frame>1</use_parent_model_frame>
            </axis>

            <physics>
                <ode>
                    <implicit_spring_damper>1</implicit_spring_damper>
                </ode>
            </physics>
        </joint>


        <!-- rotor 2 -->
        <link name='rotor2'>
            <pose>-1 0 0.21 0 0 0</pose>
            <inertial>
                <pose>0 0 0 0 0 0</pose>
                <mass>0.005</mass>
                <inertia>
                    <ixx>9.75e-07</ixx>
                    <ixy>0</ixy>
                    <ixz>0</ixz>
                    <iyy>0.000273104</iyy>
                    <iyz>0</iyz>
                    <izz>0.000274004</izz>
                </inertia>
            </inertial>
            <collision name='rotor_2_collision'>
                <pose>0 0 0 0 0 0</pose>
                <geometry>
                    <cylinder>
                        <length>0.0005</length>
                        <radius>0.128</radius>
                    </cylinder>
                </geometry>
                <surface>
                    <contact>
                        <ode />
                    </contact>
                    <friction>
                        <ode />
                    </friction>
                </surface>
            </collision>
            <visual name='rotor_2_visual'>
                <pose>0 0 0 0 0 0</pose>
                <geometry>
                    <mesh>
                        <scale>1 1 1</scale>
                        <uri>model://tarot_drone_custom/meshes/iris_prop_ccw.dae</uri>
                    </mesh>
                </geometry>
                <material>
                    <script>
                        <name>Gazebo/Gray</name>
                        <uri>file://media/materials/scripts/gazebo.material</uri>
                    </script>
                </material>
            </visual>
            <gravity>1</gravity>
            <velocity_decay />
        </link>
        <joint name='R2' type='revolute'>
            <child>rotor2</child>
            <parent>L1</parent>
            <axis>
                <xyz>0 0 1</xyz>
                <limit>
                    <lower>-1e+16</lower>
                    <upper>1e+16</upper>
                    <effort>10</effort>
                    <velocity>-1</velocity>
                </limit>
                <dynamics>
                    <damping>0.005</damping>
                </dynamics>
                <use_parent_model_frame>1</use_parent_model_frame>
            </axis>

            <physics>
                <ode>
                    <implicit_spring_damper>1</implicit_spring_damper>
                </ode>
            </physics>
        </joint>


        <!-- rotor 3 -->
        <link name='rotor3'>
            <pose>-0.5 0.86602540378 0.21 0 0 0</pose>
            <inertial>
                <pose>0 0 0 0 0 0</pose>
                <mass>0.005</mass>
                <inertia>
                    <ixx>9.75e-07</ixx>
                    <ixy>0</ixy>
                    <ixz>0</ixz>
                    <iyy>0.000273104</iyy>
                    <iyz>0</iyz>
                    <izz>0.000274004</izz>
                </inertia>
            </inertial>
            <collision name='rotor_3_collision'>
                <pose>0 0 0 0 0 0</pose>
                <geometry>
                    <cylinder>
                        <length>0.0005</length>
                        <radius>0.128</radius>
                    </cylinder>
                </geometry>
                <surface>
                    <contact>
                        <ode />
                    </contact>
                    <friction>
                        <ode />
                    </friction>
                </surface>
            </collision>
            <visual name='rotor_3_visual'>
                <pose>0 0 0 0 0 0</pose>
                <geometry>
                    <mesh>
                        <scale>1 1 1</scale>
                        <uri>model://tarot_drone_custom/meshes/iris_prop_cw.dae</uri>
                    </mesh>
                </geometry>
                <material>
                    <script>
                        <name>Gazebo/Blue</name>
                        <uri>file://media/materials/scripts/gazebo.material</uri>
                    </script>
                </material>
            </visual>
            <gravity>1</gravity>
            <velocity_decay />
        </link>
        <joint name='R3' type='revolute'>
            <child>rotor3</child>
            <parent>L1</parent>
            <axis>
                <xyz>0 0 1</xyz>
                <limit>
                    <lower>-1e+16</lower>
                    <upper>1e+16</upper>
                    <effort>10</effort>
                    <velocity>-1</velocity>
                </limit>
                <dynamics>
                    <damping>0.005</damping>
                </dynamics>
                <use_parent_model_frame>1</use_parent_model_frame>
            </axis>

            <physics>
                <ode>
                    <implicit_spring_damper>1</implicit_spring_damper>
                </ode>
            </physics>
        </joint>


        <!-- rotor 4 -->
        <link name='rotor4'>
            <pose>0.5 -0.86602540378 0.21 0 0 0</pose>
            <inertial>
                <pose>0 0 0 0 0 0</pose>
                <mass>0.005</mass>
                <inertia>
                    <ixx>9.75e-07</ixx>
                    <ixy>0</ixy>
                    <ixz>0</ixz>
                    <iyy>0.000273104</iyy>
                    <iyz>0</iyz>
                    <izz>0.000274004</izz>
                </inertia>
            </inertial>
            <collision name='rotor_4_collision'>
                <pose>0 0 0 0 0 0</pose>
                <geometry>
                    <cylinder>
                        <length>0.0005</length>
                        <radius>0.128</radius>
                    </cylinder>
                </geometry>
                <surface>
                    <contact>
                        <ode />
                    </contact>
                    <friction>
                        <ode />
                    </friction>
                </surface>
            </collision>
            <visual name='rotor_4_visual'>
                <pose>0 0 0 0 0 0</pose>
                <geometry>
                    <mesh>
                        <scale>1 1 1</scale>
                        <uri>model://tarot_drone_custom/meshes/iris_prop_ccw.dae</uri>
                    </mesh>
                </geometry>
                <material>
                    <script>
                        <name>Gazebo/Gray</name>
                        <uri>file://media/materials/scripts/gazebo.material</uri>
                    </script>
                </material>
            </visual>
            <gravity>1</gravity>
            <velocity_decay />
        </link>
        <joint name='R4' type='revolute'>
            <child>rotor4</child>
            <parent>L1</parent>
            <axis>
                <xyz>0 0 1</xyz>
                <limit>
                    <lower>-1e+16</lower>
                    <upper>1e+16</upper>
                    <effort>10</effort>
                    <velocity>-1</velocity>
                </limit>
                <dynamics>
                    <damping>0.005</damping>
                </dynamics>
                <use_parent_model_frame>1</use_parent_model_frame>
            </axis>

            <physics>
                <ode>
                    <implicit_spring_damper>1</implicit_spring_damper>
                </ode>
            </physics>
        </joint>

        <!-- rotor 5 -->
        <link name='rotor5'>
            <pose>0.5 0.86602540378 0.21 0 0 0</pose>
            <inertial>
                <pose>0 0 0 0 0 0</pose>
                <mass>0.005</mass>
                <inertia>
                    <ixx>9.75e-07</ixx>
                    <ixy>0</ixy>
                    <ixz>0</ixz>
                    <iyy>0.000273104</iyy>
                    <iyz>0</iyz>
                    <izz>0.000274004</izz>
                </inertia>
            </inertial>
            <collision name='rotor_5_collision'>
                <pose>0 0 0 0 0 0</pose>
                <geometry>
                    <cylinder>
                        <length>0.0005</length>
                        <radius>0.128</radius>
                    </cylinder>
                </geometry>
                <surface>
                    <contact>
                        <ode />
                    </contact>
                    <friction>
                        <ode />
                    </friction>
                </surface>
            </collision>
            <visual name='rotor_5_visual'>
                <pose>0 0 0 0 0 0</pose>
                <geometry>
                    <mesh>
                        <scale>1 1 1</scale>
                        <uri>model://tarot_drone_custom/meshes/iris_prop_ccw.dae</uri>
                    </mesh>
                </geometry>
                <material>
                    <script>
                        <name>Gazebo/Gray</name>
                        <uri>file://media/materials/scripts/gazebo.material</uri>
                    </script>
                </material>
            </visual>
            <gravity>1</gravity>
            <velocity_decay />
        </link>
        <joint name='R5' type='revolute'>
            <child>rotor5</child>
            <parent>L1</parent>
            <axis>
                <xyz>0 0 1</xyz>
                <limit>
                    <lower>-1e+16</lower>
                    <upper>1e+16</upper>
                    <effort>10</effort>
                    <velocity>-1</velocity>
                </limit>
                <dynamics>
                    <damping>0.005</damping>
                </dynamics>
                <use_parent_model_frame>1</use_parent_model_frame>
            </axis>

            <physics>
                <ode>
                    <implicit_spring_damper>1</implicit_spring_damper>
                </ode>
            </physics>
        </joint>


        <!-- rotor 6 -->
        <link name='rotor6'>
            <pose>-0.5 -0.86602540378 0.21 0 0 0</pose>
            <inertial>
                <pose>0 0 0 0 0 0</pose>
                <mass>0.005</mass>
                <inertia>
                    <ixx>9.75e-07</ixx>
                    <ixy>0</ixy>
                    <ixz>0</ixz>
                    <iyy>0.000273104</iyy>
                    <iyz>0</iyz>
                    <izz>0.000274004</izz>
                </inertia>
            </inertial>
            <collision name='rotor_6_collision'>
                <pose>0 0 0 0 0 0</pose>
                <geometry>
                    <cylinder>
                        <length>0.0005</length>
                        <radius>0.128</radius>
                    </cylinder>
                </geometry>
                <surface>
                    <contact>
                        <ode />
                    </contact>
                    <friction>
                        <ode />
                    </friction>
                </surface>
            </collision>
            <visual name='rotor_6_visual'>
                <pose>0 0 0 0 0 0</pose>
                <geometry>
                    <mesh>
                        <scale>1 1 1</scale>
                        <uri>model://tarot_drone_custom/meshes/iris_prop_cw.dae</uri>
                    </mesh>
                </geometry>
                <material>
                    <script>
                        <name>Gazebo/Blue</name>
                        <uri>file://media/materials/scripts/gazebo.material</uri>
                    </script>
                </material>
            </visual>
            <gravity>1</gravity>
            <velocity_decay />
        </link>
        <joint name='R6' type='revolute'>
            <child>rotor6</child>
            <parent>L1</parent>
            <axis>
                <xyz>0 0 1</xyz>
                <limit>
                    <lower>-1e+16</lower>
                    <upper>1e+16</upper>
                    <effort>10</effort>
                    <velocity>-1</velocity>
                </limit>
                <dynamics>
                    <damping>0.005</damping>
                </dynamics>
                <use_parent_model_frame>1</use_parent_model_frame>
            </axis>

            <physics>
                <ode>
                    <implicit_spring_damper>1</implicit_spring_damper>
                </ode>
            </physics>
        </joint>


        <include>
            <uri>model://gps</uri>
            <pose>0 0 0.2 0 0 0</pose>
            <name>gps</name>
        </include>

        <joint name='gps_joint' type='fixed'>
            <child>gps::link</child>
            <parent>L1</parent>
        </joint>

        <plugin name='rosbag' filename='libgazebo_multirotor_base_plugin.so'>
            <robotNamespace></robotNamespace>
            <linkName>L1</linkName>
            <rotorVelocitySlowdownSim>10</rotorVelocitySlowdownSim>
        </plugin>


        <plugin name='right_motor' filename='libgazebo_motor_model.so'>
            <robotNamespace></robotNamespace>
            <jointName>R1</jointName>
            <linkName>rotor1</linkName>
            <turningDirection>cw</turningDirection>
            <timeConstantUp>0.0125</timeConstantUp>
            <timeConstantDown>0.025</timeConstantDown>
            <maxRotVelocity>1500</maxRotVelocity>
            <motorConstant>8.54858e-06</motorConstant>
            <momentConstant>0.06</momentConstant>
            <commandSubTopic>/gazebo/command/motor_speed</commandSubTopic>
            <motorNumber>1</motorNumber>
            <rotorDragCoefficient>0.000806428</rotorDragCoefficient>
            <rollingMomentCoefficient>1e-06</rollingMomentCoefficient>
            <motorSpeedPubTopic>/motor_speed/1</motorSpeedPubTopic>
            <rotorVelocitySlowdownSim>10</rotorVelocitySlowdownSim>
        </plugin>


        <plugin name='left_motor' filename='libgazebo_motor_model.so'>
            <robotNamespace></robotNamespace>
            <jointName>R2</jointName>
            <linkName>rotor2</linkName>
            <turningDirection>ccw</turningDirection>
            <timeConstantUp>0.0125</timeConstantUp>
            <timeConstantDown>0.025</timeConstantDown>
            <maxRotVelocity>1500</maxRotVelocity>
            <motorConstant>8.54858e-06</motorConstant>
            <momentConstant>0.06</momentConstant>
            <commandSubTopic>/gazebo/command/motor_speed</commandSubTopic>
            <motorNumber>2</motorNumber>
            <rotorDragCoefficient>0.000806428</rotorDragCoefficient>
            <rollingMomentCoefficient>1e-06</rollingMomentCoefficient>
            <motorSpeedPubTopic>/motor_speed/2</motorSpeedPubTopic>
            <rotorVelocitySlowdownSim>10</rotorVelocitySlowdownSim>
        </plugin>


        <plugin name='front_left_motor' filename='libgazebo_motor_model.so'>
            <robotNamespace></robotNamespace>
            <jointName>R3</jointName>
            <linkName>rotor3</linkName>
            <turningDirection>cw</turningDirection>
            <timeConstantUp>0.0125</timeConstantUp>
            <timeConstantDown>0.025</timeConstantDown>
            <maxRotVelocity>1500</maxRotVelocity>
            <motorConstant>8.54858e-06</motorConstant>
            <momentConstant>0.06</momentConstant>
            <commandSubTopic>/gazebo/command/motor_speed</commandSubTopic>
            <motorNumber>3</motorNumber>
            <rotorDragCoefficient>0.000806428</rotorDragCoefficient>
            <rollingMomentCoefficient>1e-06</rollingMomentCoefficient>
            <motorSpeedPubTopic>/motor_speed/3</motorSpeedPubTopic>
            <rotorVelocitySlowdownSim>10</rotorVelocitySlowdownSim>
        </plugin>

        <plugin name='back_left_motor' filename='libgazebo_motor_model.so'>
            <robotNamespace></robotNamespace>
            <jointName>R4</jointName>
            <linkName>rotor4</linkName>
            <turningDirection>ccw</turningDirection>
            <timeConstantUp>0.0125</timeConstantUp>
            <timeConstantDown>0.025</timeConstantDown>
            <maxRotVelocity>1500</maxRotVelocity>
            <motorConstant>8.54858e-06</motorConstant>
            <momentConstant>0.06</momentConstant>
            <commandSubTopic>/gazebo/command/motor_speed</commandSubTopic>
            <motorNumber>4</motorNumber>
            <rotorDragCoefficient>0.000806428</rotorDragCoefficient>
            <rollingMomentCoefficient>1e-06</rollingMomentCoefficient>
            <motorSpeedPubTopic>/motor_speed/4</motorSpeedPubTopic>
            <rotorVelocitySlowdownSim>10</rotorVelocitySlowdownSim>
        </plugin>

        <plugin name='front_right_motor' filename='libgazebo_motor_model.so'>
            <robotNamespace></robotNamespace>
            <jointName>R5</jointName>
            <linkName>rotor5</linkName>
            <turningDirection>ccw</turningDirection>
            <timeConstantUp>0.0125</timeConstantUp>
            <timeConstantDown>0.025</timeConstantDown>
            <maxRotVelocity>1500</maxRotVelocity>
            <motorConstant>8.54858e-06</motorConstant>
            <momentConstant>0.06</momentConstant>
            <commandSubTopic>/gazebo/command/motor_speed</commandSubTopic>
            <motorNumber>5</motorNumber>
            <rotorDragCoefficient>0.000806428</rotorDragCoefficient>
            <rollingMomentCoefficient>1e-06</rollingMomentCoefficient>
            <motorSpeedPubTopic>/motor_speed/5</motorSpeedPubTopic>
            <rotorVelocitySlowdownSim>10</rotorVelocitySlowdownSim>
        </plugin>

        <plugin name='back_left_motor' filename='libgazebo_motor_model.so'>
            <robotNamespace></robotNamespace>
            <jointName>R6</jointName>
            <linkName>rotor6</linkName>
            <turningDirection>cw</turningDirection>
            <timeConstantUp>0.0125</timeConstantUp>
            <timeConstantDown>0.025</timeConstantDown>
            <maxRotVelocity>1500</maxRotVelocity>
            <motorConstant>8.54858e-06</motorConstant>
            <momentConstant>0.06</momentConstant>
            <commandSubTopic>/gazebo/command/motor_speed</commandSubTopic>
            <motorNumber>6</motorNumber>
            <rotorDragCoefficient>0.000806428</rotorDragCoefficient>
            <rollingMomentCoefficient>1e-06</rollingMomentCoefficient>
            <motorSpeedPubTopic>/motor_speed/6</motorSpeedPubTopic>
            <rotorVelocitySlowdownSim>10</rotorVelocitySlowdownSim>
        </plugin>

        <plugin name='groundtruth_plugin' filename='libgazebo_groundtruth_plugin.so'>
            <robotNamespace />
        </plugin>

        <plugin name='magnetometer_plugin' filename='libgazebo_magnetometer_plugin.so'>
            <robotNamespace />
            <pubRate>100</pubRate>
            <noiseDensity>0.0004</noiseDensity>
            <randomWalk>6.4e-06</randomWalk>
            <biasCorrelationTime>600</biasCorrelationTime>
            <magTopic>/mag</magTopic>
        </plugin>
        <plugin name='barometer_plugin' filename='libgazebo_barometer_plugin.so'>
            <robotNamespace />
            <pubRate>50</pubRate>
            <baroTopic>/baro</baroTopic>
        </plugin>

        <plugin name='mavlink_interface' filename='libgazebo_mavlink_interface.so'>
            <robotNamespace></robotNamespace>
            <imuSubTopic>/imu</imuSubTopic>
            <magSubTopic>/mag</magSubTopic>
            <baroSubTopic>/baro</baroSubTopic>
            <mavlink_addr>INADDR_ANY</mavlink_addr>
            <mavlink_tcp_port>4560</mavlink_tcp_port>
            <mavlink_udp_port>14560</mavlink_udp_port>
            <serialEnabled>0</serialEnabled>
            <serialDevice>/dev/ttyACM0</serialDevice>
            <baudRate>921600</baudRate>
            <qgc_addr>INADDR_ANY</qgc_addr>
            <qgc_udp_port>14550</qgc_udp_port>
            <sdk_addr>INADDR_ANY</sdk_addr>
            <sdk_udp_port>14540</sdk_udp_port>
            <hil_mode>0</hil_mode>
            <hil_state_level>false</hil_state_level>
            <enable_lockstep>true</enable_lockstep>
            <use_tcp>true</use_tcp>
            <motorSpeedCommandPubTopic>/gazebo/command/motor_speed</motorSpeedCommandPubTopic>
            <control_channels>
                <channel name="rotor1">
                    <input_index>1</input_index>
                    <input_offset>0</input_offset>
                    <input_scaling>1500</input_scaling>
                    <zero_position_disarmed>0</zero_position_disarmed>
                    <zero_position_armed>100</zero_position_armed>
                    <joint_control_type>velocity</joint_control_type>
                </channel>

                <channel name="rotor2">
                    <input_index>2</input_index>
                    <input_offset>0</input_offset>
                    <input_scaling>1500</input_scaling>
                    <zero_position_disarmed>0</zero_position_disarmed>
                    <zero_position_armed>100</zero_position_armed>
                    <joint_control_type>velocity</joint_control_type>
                </channel>


                <channel name="rotor3">
                    <input_index>3</input_index>
                    <input_offset>0</input_offset>
                    <input_scaling>1500</input_scaling>
                    <zero_position_disarmed>0</zero_position_disarmed>
                    <zero_position_armed>100</zero_position_armed>
                    <joint_control_type>velocity</joint_control_type>
                </channel>


                <channel name="rotor4">
                    <input_index>4</input_index>
                    <input_offset>0</input_offset>
                    <input_scaling>1500</input_scaling>
                    <zero_position_disarmed>0</zero_position_disarmed>
                    <zero_position_armed>100</zero_position_armed>
                    <joint_control_type>velocity</joint_control_type>
                </channel>

                <channel name="rotor5">
                    <input_index>5</input_index>
                    <input_offset>0</input_offset>
                    <input_scaling>1500</input_scaling>
                    <zero_position_disarmed>0</zero_position_disarmed>
                    <zero_position_armed>100</zero_position_armed>
                    <joint_control_type>velocity</joint_control_type>
                </channel>

                <channel name="rotor6">
                    <input_index>6</input_index>
                    <input_offset>0</input_offset>
                    <input_scaling>1500</input_scaling>
                    <zero_position_disarmed>0</zero_position_disarmed>
                    <zero_position_armed>100</zero_position_armed>
                    <joint_control_type>velocity</joint_control_type>
                </channel>

            </control_channels>
        </plugin>


        <plugin name='gazebo_imu_plugin' filename='libgazebo_imu_plugin.so'>
            <robotNamespace></robotNamespace>
            <linkName>L1</linkName>
            <imuTopic>/imu</imuTopic>
            <gyroscopeNoiseDensity>0.0003394</gyroscopeNoiseDensity>
            <gyroscopeRandomWalk>3.8785e-05</gyroscopeRandomWalk>
            <gyroscopeBiasCorrelationTime>1000.0</gyroscopeBiasCorrelationTime>
            <gyroscopeTurnOnBiasSigma>0.0087</gyroscopeTurnOnBiasSigma>
            <accelerometerNoiseDensity>0.004</accelerometerNoiseDensity>
            <accelerometerRandomWalk>0.006</accelerometerRandomWalk>
            <accelerometerBiasCorrelationTime>300.0</accelerometerBiasCorrelationTime>
            <accelerometerTurnOnBiasSigma>0.196</accelerometerTurnOnBiasSigma>
        </plugin>


    </model>
</sdf>