<sdf version='1.7'>
  <model name='tarot_drone_custom'>
    <link name='L1'>
      <inertial>
        <pose>-0.008585 -0.128542 0.236472 0 -0 0</pose>
        <mass>0.98937</mass>
        <inertia>
          <ixx>0.0257323</ixx>
          <ixy>-3.3722e-05</ixy>
          <ixz>-0.000448122</ixz>
          <iyy>0.0245817</iyy>
          <iyz>-3.29026e-05</iyz>
          <izz>0.049121</izz>
        </inertia>
      </inertial>

      <!-- collision is below-->
      <collision name='L1_collision'>
        <pose>0 0 0 0 -0 0</pose>
        <geometry>
          <mesh>
            <scale>1 1 1</scale>
            <uri>model://tarot_drone_custom/meshes/L1.STL</uri>
          </mesh>
        </geometry>
      </collision>
      <collision name='L1_fixed_joint_lump__arm1_collision_1'>
        <pose>-0.07976 -0.070711 0.07883 1.5796 -0.093345 -0.52435</pose>
        <geometry>
          <mesh>
            <scale>1 1 1</scale>
            <uri>model://tarot_drone_custom/meshes/arm1.STL</uri>
          </mesh>
        </geometry>
      </collision>
      <collision name='L1_fixed_joint_lump__arm2_collision_2'>
        <pose>-0.093645 -0.16386 0.078587 1.562 -0.093345 0.52435</pose>
        <geometry>
          <mesh>
            <scale>1 1 1</scale>
            <uri>model://tarot_drone_custom/meshes/arm2.STL</uri>
          </mesh>
        </geometry>
      </collision>
      <collision name='L1_fixed_joint_lump__arm3_collision_3'>
        <pose>-0.033857 -0.22248 0.079751 1.5533 -0.078222 1.5722</pose>
        <geometry>
          <mesh>
            <scale>1 1 1</scale>
            <uri>model://tarot_drone_custom/meshes/arm3.STL</uri>
          </mesh>
        </geometry>
      </collision>
      <collision name='L1_fixed_joint_lump__arm4_collision_4'>
        <pose>0.067676 -0.18801 0.081403 1.5621 -0.063116 2.6186</pose>
        <geometry>
          <mesh>
            <scale>1 1 1</scale>
            <uri>model://tarot_drone_custom/meshes/arm4.STL</uri>
          </mesh>
        </geometry>
      </collision>
      <collision name='L1_fixed_joint_lump__arm5_collision_5'>
        <pose>0.081562 -0.094858 0.081645 1.5795 -0.063116 -2.6186</pose>
        <geometry>
          <mesh>
            <scale>1 1 1</scale>
            <uri>model://tarot_drone_custom/meshes/arm5.STL</uri>
          </mesh>
        </geometry>
      </collision>
      <collision name='L1_fixed_joint_lump__arm6_collision_6'>
        <pose>0.021769 -0.036178 0.080722 1.5883 -0.078222 -1.5722</pose>
        <geometry>
          <mesh>
            <scale>1 1 1</scale>
            <uri>model://tarot_drone_custom/meshes/arm6.STL</uri>
          </mesh>
        </geometry>
      </collision>
      <collision name='L1_fixed_joint_lump__t1_collision_7'>
        <pose>-0.12808 -0.27468 0.019425 0 -1.5432 0</pose>
        <geometry>
          <mesh>
            <scale>1 1 1</scale>
            <uri>model://tarot_drone_custom/meshes/t1.STL</uri>
          </mesh>
        </geometry>
      </collision>


      <!-- visual is below-->
      <visual name='L1_visual'>
        <pose>0 0 0 0 -0 0</pose>
        <geometry>
          <mesh>
            <scale>1 1 1</scale>
            <uri>model://tarot_drone_custom/meshes/L1.STL</uri>
          </mesh>
        </geometry>
      </visual>
      <visual name='L1_fixed_joint_lump__arm1_visual_1'>
        <pose>-0.07976 -0.070711 0.07883 1.5796 -0.093345 -0.52435</pose>
        <geometry>
          <mesh>
            <scale>1 1 1</scale>
            <uri>model://tarot_drone_custom/meshes/arm1.STL</uri>
          </mesh>
        </geometry>
      </visual>
      <visual name='L1_fixed_joint_lump__arm2_visual_2'>
        <pose>-0.093645 -0.16386 0.078587 1.562 -0.093345 0.52435</pose>
        <geometry>
          <mesh>
            <scale>1 1 1</scale>
            <uri>model://tarot_drone_custom/meshes/arm2.STL</uri>
          </mesh>
        </geometry>
      </visual>
      <visual name='L1_fixed_joint_lump__arm3_visual_3'>
        <pose>-0.033857 -0.22248 0.079751 1.5533 -0.078222 1.5722</pose>
        <geometry>
          <mesh>
            <scale>1 1 1</scale>
            <uri>model://tarot_drone_custom/meshes/arm3.STL</uri>
          </mesh>
        </geometry>
      </visual>
      <visual name='L1_fixed_joint_lump__arm4_visual_4'>
        <pose>0.067676 -0.18801 0.081403 1.5621 -0.063116 2.6186</pose>
        <geometry>
          <mesh>
            <scale>1 1 1</scale>
            <uri>model://tarot_drone_custom/meshes/arm4.STL</uri>
          </mesh>
        </geometry>
      </visual>
      <visual name='L1_fixed_joint_lump__arm5_visual_5'>
        <pose>0.081562 -0.094858 0.081645 1.5795 -0.063116 -2.6186</pose>
        <geometry>
          <mesh>
            <scale>1 1 1</scale>
            <uri>model://tarot_drone_custom/meshes/arm5.STL</uri>
          </mesh>
        </geometry>
      </visual>
      <visual name='L1_fixed_joint_lump__arm6_visual_6'>
        <pose>0.021769 -0.036178 0.080722 1.5883 -0.078222 -1.5722</pose>
        <geometry>
          <mesh>
            <scale>1 1 1</scale>
            <uri>model://tarot_drone_custom/meshes/arm6.STL</uri>
          </mesh>
        </geometry>
      </visual>
      <visual name='L1_fixed_joint_lump__t1_visual_7'>
        <pose>-0.12808 -0.27468 0.019425 0 -1.5432 0</pose>
        <geometry>
          <mesh>
            <scale>1 1 1</scale>
            <uri>model://tarot_drone_custom/meshes/t1.STL</uri>
          </mesh>
        </geometry>
      </visual>
    </link>


    <joint name='R1' type='revolute'>
      <pose relative_to='L1'>-0.185622 -0.435533 0.273732 -1.58817 0.002179 1.69636</pose>
      <parent>L1</parent>
      <child>rotor1</child>
      <axis>
        <xyz>0 1 0</xyz>
        <limit>
          <lower>-1e+16</lower>
          <upper>1e+16</upper>
        </limit>
        <dynamics>
          <spring_reference>0</spring_reference>
          <spring_stiffness>0</spring_stiffness>
        </dynamics>
      </axis>
    </joint>
    <link name='rotor1'>
      <pose relative_to='R1'>0 0 0 0 -0 0</pose>
      <inertial>
        <pose>-0 -0.002498 -0 0 -0 0</pose>
        <mass>0.0602684</mass>
        <inertia>
          <ixx>2.14233e-06</ixx>
          <ixy>8.87516e-21</ixy>
          <ixz>6.02426e-19</ixz>
          <iyy>0.000585026</iyy>
          <iyz>5.06761e-20</iyz>
          <izz>0.000583134</izz>
        </inertia>
      </inertial>
      <collision name='rotor1_collision'>
        <pose>0 0 0 0 -0 0</pose>
        <geometry>
          <mesh>
            <scale>1 1 1</scale>
            <uri>model://tarot_drone_custom/meshes/rotor1.STL</uri>
          </mesh>
        </geometry>
      </collision>
      <visual name='rotor1_visual'>
        <pose>0 0 0 0 -0 0</pose>
        <geometry>
          <mesh>
            <scale>1 1 1</scale>
            <uri>model://tarot_drone_custom/meshes/rotor1.STL</uri>
          </mesh>
        </geometry>
      </visual>
    </link>
    <joint name='R2' type='revolute'>
      <pose relative_to='L1'>0.167596 -0.43498 0.279923 -1.56472 0.016418 -2.78779</pose>
      <parent>L1</parent>
      <child>rotor2</child>
      <axis>
        <xyz>0 1 0</xyz>
        <limit>
          <lower>-1e+16</lower>
          <upper>1e+16</upper>
        </limit>
        <dynamics>
          <spring_reference>0</spring_reference>
          <spring_stiffness>0</spring_stiffness>
        </dynamics>
      </axis>
    </joint>
    <link name='rotor2'>
      <pose relative_to='R2'>0 0 0 0 -0 0</pose>
      <inertial>
        <pose>-0 -0.002498 0 0 -0 0</pose>
        <mass>0.0602684</mass>
        <inertia>
          <ixx>2.14233e-06</ixx>
          <ixy>8.40914e-20</ixy>
          <ixz>1.50295e-19</ixz>
          <iyy>0.000585026</iyy>
          <iyz>8.79872e-21</iyz>
          <izz>0.000583134</izz>
        </inertia>
      </inertial>
      <collision name='rotor2_collision'>
        <pose>0 0 0 0 -0 0</pose>
        <geometry>
          <mesh>
            <scale>1 1 1</scale>
            <uri>model://tarot_drone_custom/meshes/rotor2.STL</uri>
          </mesh>
        </geometry>
      </collision>
      <visual name='rotor2_visual'>
        <pose>0 0 0 0 -0 0</pose>
        <geometry>
          <mesh>
            <scale>1 1 1</scale>
            <uri>model://tarot_drone_custom/meshes/rotor2.STL</uri>
          </mesh>
        </geometry>
      </visual>
    </link>
    <joint name='R3' type='revolute'>
      <pose relative_to='L1'>0.329812 -0.128776 0.282859 -1.55961 -0.013381 -0.694065</pose>
      <parent>L1</parent>
      <child>rotor3</child>
      <axis>
        <xyz>0 1 0</xyz>
        <limit>
          <lower>-1e+16</lower>
          <upper>1e+16</upper>
        </limit>
        <dynamics>
          <spring_reference>0</spring_reference>
          <spring_stiffness>0</spring_stiffness>
        </dynamics>
      </axis>
    </joint>
    <link name='rotor3'>
      <pose relative_to='R3'>0 0 0 0 -0 0</pose>
      <inertial>
        <pose>0 -0.002498 0 0 -0 0</pose>
        <mass>0.0602684</mass>
        <inertia>
          <ixx>2.14233e-06</ixx>
          <ixy>7.50476e-19</ixy>
          <ixz>-6.22146e-19</ixz>
          <iyy>0.000585026</iyy>
          <iyz>-1.11877e-21</iyz>
          <izz>0.000583134</izz>
        </inertia>
      </inertial>
      <collision name='rotor3_collision'>
        <pose>0 0 0 0 -0 0</pose>
        <geometry>
          <mesh>
            <scale>1 1 1</scale>
            <uri>model://tarot_drone_custom/meshes/rotor3.STL</uri>
          </mesh>
        </geometry>
      </collision>
      <visual name='rotor3_visual'>
        <pose>0 0 0 0 -0 0</pose>
        <geometry>
          <mesh>
            <scale>1 1 1</scale>
            <uri>model://tarot_drone_custom/meshes/rotor3.STL</uri>
          </mesh>
        </geometry>
      </visual>
    </link>
    <joint name='R4' type='revolute'>
      <pose relative_to='L1'>0.166676 0.176813 0.279878 -1.58118 0.013992 2.5003</pose>
      <parent>L1</parent>
      <child>rotor4</child>
      <axis>
        <xyz>0 1 0</xyz>
        <limit>
          <lower>-1e+16</lower>
          <upper>1e+16</upper>
        </limit>
        <dynamics>
          <spring_reference>0</spring_reference>
          <spring_stiffness>0</spring_stiffness>
        </dynamics>
      </axis>
    </joint>
    <link name='rotor4'>
      <pose relative_to='R4'>0 0 0 0 -0 0</pose>
      <inertial>
        <pose>-0 -0.002498 -0 0 -0 0</pose>
        <mass>0.0602684</mass>
        <inertia>
          <ixx>2.14233e-06</ixx>
          <ixy>-5.57189e-19</ixy>
          <ixz>1.81053e-20</ixz>
          <iyy>0.000585026</iyy>
          <iyz>8.5347e-21</iyz>
          <izz>0.000583134</izz>
        </inertia>
      </inertial>
      <collision name='rotor4_collision'>
        <pose>0 0 0 0 -0 0</pose>
        <geometry>
          <mesh>
            <scale>1 1 1</scale>
            <uri>model://tarot_drone_custom/meshes/rotor4.STL</uri>
          </mesh>
        </geometry>
      </collision>
      <visual name='rotor4_visual'>
        <pose>0 0 0 0 -0 0</pose>
        <geometry>
          <mesh>
            <scale>1 1 1</scale>
            <uri>model://tarot_drone_custom/meshes/rotor4.STL</uri>
          </mesh>
        </geometry>
      </visual>
    </link>
    <joint name='R5' type='revolute'>
      <pose relative_to='L1'>-0.186549 0.176257 0.273744 -1.58819 -0.000438 1.54641</pose>
      <parent>L1</parent>
      <child>rotor5</child>
      <axis>
        <xyz>0 1 0</xyz>
        <limit>
          <lower>-1e+16</lower>
          <upper>1e+16</upper>
        </limit>
        <dynamics>
          <spring_reference>0</spring_reference>
          <spring_stiffness>0</spring_stiffness>
        </dynamics>
      </axis>
    </joint>
    <link name='rotor5'>
      <pose relative_to='R5'>0 0 0 0 -0 0</pose>
      <inertial>
        <pose>-0 -0.002498 -0 0 -0 0</pose>
        <mass>0.0602684</mass>
        <inertia>
          <ixx>2.14233e-06</ixx>
          <ixy>-3.98938e-19</ixy>
          <ixz>7.36747e-19</ixz>
          <iyy>0.000585026</iyy>
          <iyz>-5.50972e-21</iyz>
          <izz>0.000583134</izz>
        </inertia>
      </inertial>
      <collision name='rotor5_collision'>
        <pose>0 0 0 0 -0 0</pose>
        <geometry>
          <mesh>
            <scale>1 1 1</scale>
            <uri>model://tarot_drone_custom/meshes/rotor5.STL</uri>
          </mesh>
        </geometry>
      </collision>
      <visual name='rotor5_visual'>
        <pose>0 0 0 0 -0 0</pose>
        <geometry>
          <mesh>
            <scale>1 1 1</scale>
            <uri>model://tarot_drone_custom/meshes/rotor5.STL</uri>
          </mesh>
        </geometry>
      </visual>
    </link>
    <joint name='R6' type='revolute'>
      <pose relative_to='L1'>-0.348771 -0.129856 0.271019 -1.56159 -0.01483 -0.5552</pose>
      <parent>L1</parent>
      <child>rotor6</child>
      <axis>
        <xyz>0 1 0</xyz>
        <limit>
          <lower>-1e+16</lower>
          <upper>1e+16</upper>
        </limit>
        <dynamics>
          <spring_reference>0</spring_reference>
          <spring_stiffness>0</spring_stiffness>
        </dynamics>
      </axis>
    </joint>
    <link name='rotor6'>
      <pose relative_to='R6'>0 0 0 0 -0 0</pose>
      <inertial>
        <pose>0 -0.002498 0 0 -0 0</pose>
        <mass>0.0602684</mass>
        <inertia>
          <ixx>2.14233e-06</ixx>
          <ixy>7.80899e-19</ixy>
          <ixz>2.90956e-19</ixz>
          <iyy>0.000585026</iyy>
          <iyz>7.53935e-22</iyz>
          <izz>0.000583134</izz>
        </inertia>
      </inertial>
      <collision name='rotor6_collision'>
        <pose>0 0 0 0 -0 0</pose>
        <geometry>
          <mesh>
            <scale>1 1 1</scale>
            <uri>model://tarot_drone_custom/meshes/rotor6.STL</uri>
          </mesh>
        </geometry>
      </collision>
      <visual name='rotor6_visual'>
        <pose>0 0 0 0 -0 0</pose>
        <geometry>
          <mesh>
            <scale>1 1 1</scale>
            <uri>model://tarot_drone_custom/meshes/rotor6.STL</uri>
          </mesh>
        </geometry>
      </visual>
    </link>
  </model>
</sdf>